INFO  [alembic.runtime.migration] Context impl PostgresqlImpl.
INFO  [alembic.runtime.migration] Will assume transactional DDL.
INFO  [alembic.runtime.migration] Running upgrade  -> 6f1b94ebef45, initial_setup_enable_postgis
INFO  [alembic.runtime.migration] Running upgrade 6f1b94ebef45 -> 2f68e3f132f5, create warehouses table
Traceback (most recent call last):
  File "/home/lucasg/anaconda3/envs/demeterai_docs/lib/python3.12/site-packages/sqlalchemy/engine/base.py", line 1967, in _exec_single_context
    self.dialect.do_execute(
  File "/home/lucasg/anaconda3/envs/demeterai_docs/lib/python3.12/site-packages/sqlalchemy/engine/default.py", line 951, in do_execute
    cursor.execute(statement, parameters)
psycopg2.errors.DuplicateObject: type "warehouse_type_enum" already exists


The above exception was the direct cause of the following exception:

Traceback (most recent call last):
  File "/home/lucasg/anaconda3/envs/demeterai_docs/bin/alembic", line 7, in <module>
    sys.exit(main())
             ^^^^^^
  File "/home/lucasg/anaconda3/envs/demeterai_docs/lib/python3.12/site-packages/alembic/config.py", line 636, in main
    CommandLine(prog=prog).main(argv=argv)
  File "/home/lucasg/anaconda3/envs/demeterai_docs/lib/python3.12/site-packages/alembic/config.py", line 626, in main
    self.run_cmd(cfg, options)
  File "/home/lucasg/anaconda3/envs/demeterai_docs/lib/python3.12/site-packages/alembic/config.py", line 603, in run_cmd
    fn(
  File "/home/lucasg/anaconda3/envs/demeterai_docs/lib/python3.12/site-packages/alembic/command.py", line 406, in upgrade
    script.run_env()
  File "/home/lucasg/anaconda3/envs/demeterai_docs/lib/python3.12/site-packages/alembic/script/base.py", line 586, in run_env
    util.load_python_file(self.dir, "env.py")
  File "/home/lucasg/anaconda3/envs/demeterai_docs/lib/python3.12/site-packages/alembic/util/pyfiles.py", line 95, in load_python_file
    module = load_module_py(module_id, path)
             ^^^^^^^^^^^^^^^^^^^^^^^^^^^^^^^
  File "/home/lucasg/anaconda3/envs/demeterai_docs/lib/python3.12/site-packages/alembic/util/pyfiles.py", line 113, in load_module_py
    spec.loader.exec_module(module)  # type: ignore
    ^^^^^^^^^^^^^^^^^^^^^^^^^^^^^^^
  File "<frozen importlib._bootstrap_external>", line 999, in exec_module
  File "<frozen importlib._bootstrap>", line 488, in _call_with_frames_removed
  File "/home/lucasg/proyectos/DemeterDocs/alembic/env.py", line 105, in <module>
    run_migrations_online()
  File "/home/lucasg/proyectos/DemeterDocs/alembic/env.py", line 99, in run_migrations_online
    context.run_migrations()
  File "<string>", line 8, in run_migrations
  File "/home/lucasg/anaconda3/envs/demeterai_docs/lib/python3.12/site-packages/alembic/runtime/environment.py", line 946, in run_migrations
    self.get_context().run_migrations(**kw)
  File "/home/lucasg/anaconda3/envs/demeterai_docs/lib/python3.12/site-packages/alembic/runtime/migration.py", line 623, in run_migrations
    step.migration_fn(**kw)
  File "/home/lucasg/proyectos/DemeterDocs/alembic/versions/2f68e3f132f5_create_warehouses_table.py", line 54, in upgrade
    op.create_table(
  File "<string>", line 8, in create_table
  File "<string>", line 3, in create_table
  File "/home/lucasg/anaconda3/envs/demeterai_docs/lib/python3.12/site-packages/alembic/operations/ops.py", line 1318, in create_table
    return operations.invoke(op)
           ^^^^^^^^^^^^^^^^^^^^^
  File "/home/lucasg/anaconda3/envs/demeterai_docs/lib/python3.12/site-packages/alembic/operations/base.py", line 442, in invoke
    return fn(self, operation)
           ^^^^^^^^^^^^^^^^^^^
  File "/home/lucasg/anaconda3/envs/demeterai_docs/lib/python3.12/site-packages/alembic/operations/toimpl.py", line 143, in create_table
    operations.impl.create_table(table, **kw)
  File "/home/lucasg/anaconda3/envs/demeterai_docs/lib/python3.12/site-packages/alembic/ddl/impl.py", line 403, in create_table
    table.dispatch.before_create(
  File "/home/lucasg/anaconda3/envs/demeterai_docs/lib/python3.12/site-packages/sqlalchemy/event/attr.py", line 497, in __call__
    fn(*args, **kw)
  File "/home/lucasg/anaconda3/envs/demeterai_docs/lib/python3.12/site-packages/sqlalchemy/util/langhelpers.py", line 937, in __call__
    return getattr(self.target, self.name)(*arg, **kw)
           ^^^^^^^^^^^^^^^^^^^^^^^^^^^^^^^^^^^^^^^^^^^
  File "/home/lucasg/anaconda3/envs/demeterai_docs/lib/python3.12/site-packages/sqlalchemy/sql/sqltypes.py", line 1152, in _on_table_create
    t._on_table_create(target, bind, **kw)
  File "/home/lucasg/anaconda3/envs/demeterai_docs/lib/python3.12/site-packages/sqlalchemy/dialects/postgresql/named_types.py", line 113, in _on_table_create
    self.create(bind=bind, checkfirst=checkfirst)
  File "/home/lucasg/anaconda3/envs/demeterai_docs/lib/python3.12/site-packages/sqlalchemy/dialects/postgresql/named_types.py", line 369, in create
    super().create(bind, checkfirst=checkfirst)
  File "/home/lucasg/anaconda3/envs/demeterai_docs/lib/python3.12/site-packages/sqlalchemy/dialects/postgresql/named_types.py", line 56, in create
    bind._run_ddl_visitor(self.DDLGenerator, self, checkfirst=checkfirst)
  File "/home/lucasg/anaconda3/envs/demeterai_docs/lib/python3.12/site-packages/sqlalchemy/engine/base.py", line 2459, in _run_ddl_visitor
    ).traverse_single(element)
      ^^^^^^^^^^^^^^^^^^^^^^^^
  File "/home/lucasg/anaconda3/envs/demeterai_docs/lib/python3.12/site-packages/sqlalchemy/sql/visitors.py", line 661, in traverse_single
    return meth(obj, **kw)
           ^^^^^^^^^^^^^^^
  File "/home/lucasg/anaconda3/envs/demeterai_docs/lib/python3.12/site-packages/sqlalchemy/dialects/postgresql/named_types.py", line 186, in visit_enum
    self.connection.execute(CreateEnumType(enum))
  File "/home/lucasg/anaconda3/envs/demeterai_docs/lib/python3.12/site-packages/sqlalchemy/engine/base.py", line 1419, in execute
    return meth(
           ^^^^^
  File "/home/lucasg/anaconda3/envs/demeterai_docs/lib/python3.12/site-packages/sqlalchemy/sql/ddl.py", line 187, in _execute_on_connection
    return connection._execute_ddl(
           ^^^^^^^^^^^^^^^^^^^^^^^^
  File "/home/lucasg/anaconda3/envs/demeterai_docs/lib/python3.12/site-packages/sqlalchemy/engine/base.py", line 1530, in _execute_ddl
    ret = self._execute_context(
          ^^^^^^^^^^^^^^^^^^^^^^
  File "/home/lucasg/anaconda3/envs/demeterai_docs/lib/python3.12/site-packages/sqlalchemy/engine/base.py", line 1846, in _execute_context
    return self._exec_single_context(
           ^^^^^^^^^^^^^^^^^^^^^^^^^^
  File "/home/lucasg/anaconda3/envs/demeterai_docs/lib/python3.12/site-packages/sqlalchemy/engine/base.py", line 1986, in _exec_single_context
    self._handle_dbapi_exception(
  File "/home/lucasg/anaconda3/envs/demeterai_docs/lib/python3.12/site-packages/sqlalchemy/engine/base.py", line 2355, in _handle_dbapi_exception
    raise sqlalchemy_exception.with_traceback(exc_info[2]) from e
  File "/home/lucasg/anaconda3/envs/demeterai_docs/lib/python3.12/site-packages/sqlalchemy/engine/base.py", line 1967, in _exec_single_context
    self.dialect.do_execute(
  File "/home/lucasg/anaconda3/envs/demeterai_docs/lib/python3.12/site-packages/sqlalchemy/engine/default.py", line 951, in do_execute
    cursor.execute(statement, parameters)
sqlalchemy.exc.ProgrammingError: (psycopg2.errors.DuplicateObject) type "warehouse_type_enum" already exists

[SQL: CREATE TYPE warehouse_type_enum AS ENUM ('greenhouse', 'shadehouse', 'open_field', 'tunnel')]
(Background on this error at: https://sqlalche.me/e/20/f405)
